Workbook

Sheet Mapa Injetoras
C1: MAPA INJETORAS
D3: ENGEL 32 | J3: ROMI 40 | M3: ROMI 09
D4: =IFERROR(VLOOKUP(E5,'Dados dos moldes'!$B$2:$C$250,2,FALSE),"") -> Corpo 07 Vip retrátil | J4: =IFERROR(VLOOKUP(K5,'Dados dos moldes'!$B$2:$C$250,2,FALSE),"") -> Corpo Destaq | M4: =IFERROR(VLOOKUP(N5,'Dados dos moldes'!$B$2:$C$250,2,FALSE),"") -> Corpo Q.B
D5: MOLDE | E5: 183 | J5: MOLDE | K5: 164 | M5: MOLDE | N5: 116A
D7: ENGEL 31 | G7: ARBURG 52 | J7: ARBURG 36 | M7: ROMI 29
D8: =IFERROR(VLOOKUP(E9,'Dados dos moldes'!$B$2:$C$250,2,FALSE),"") -> Sem Molde | G8: =IFERROR(VLOOKUP(H9,'Dados dos moldes'!$B$2:$C$250,2,FALSE),"") -> Corpo 07 / Economic | J8: =IFERROR(VLOOKUP(K9,'Dados dos moldes'!$B$2:$C$250,2,FALSE),"") -> Tampa Esf. Top | M8: =IFERROR(VLOOKUP(N9,'Dados dos moldes'!$B$2:$C$250,2,FALSE),"") -> Tampa Pincel
D9: MOLDE | E9: - | G9: MOLDE | H9: 192 | J9: MOLDE | K9: 107 | M9: MOLDE | N9: 145B
H10: ,
D11: ENGEL 08 | J11: ARBURG 48 | M11: ROMI 30
D12: =IFERROR(VLOOKUP(E13,'Dados dos moldes'!$B$2:$C$250,2,FALSE),"") -> Tampa Neo Pen | J12: =IFERROR(VLOOKUP(K13,'Dados dos moldes'!$B$2:$C$250,2,FALSE),"") -> Corpo Top | M12: =IFERROR(VLOOKUP(N13,'Dados dos moldes'!$B$2:$C$250,2,FALSE),"") -> Tampinha Q.B / Pincel
D13: MOLDE | E13: 169 | J13: MOLDE | K13: 190 | M13: MOLDE | N13: 145C
D15: ENGEL 07 | J15: ARBURG 49 | M15: ROMI 39
D16: =IFERROR(VLOOKUP(E17,'Dados dos moldes'!$B$2:$C$250,2,FALSE),"") -> Corpo Pincel | J16: =IFERROR(VLOOKUP(K17,'Dados dos moldes'!$B$2:$C$250,2,FALSE),"") -> Corpo NPG | M16: =IFERROR(VLOOKUP(N17,'Dados dos moldes'!$B$2:$C$250,2,FALSE),"") -> Tampa Cônica
D17: MOLDE | E17: 191 | J17: MOLDE | K17: 199 | M17: MOLDE | N17: 145A
D19: ENGEL 34 | J19: ARBURG 50 | M19: ROMI 44
D20: =IFERROR(VLOOKUP(E21,'Dados dos moldes'!$B$2:$C$250,2,FALSE),"") -> Conexão Esferográficas | J20: =IFERROR(VLOOKUP(K21,'Dados dos moldes'!$B$2:$C$250,2,FALSE),"") -> Tampa Esf. 07 | M20: =IFERROR(VLOOKUP(N21,'Dados dos moldes'!$B$2:$C$250,2,FALSE),"") -> Tampa Esf. Top
D21: MOLDE | E21: 200 | J21: MOLDE | K21: 181 | M21: MOLDE | N21: 139
D23: ENGEL 35 | G23: ARBURG 51 | J23: ROMI 37 | M23: ROMI 45
D24: =IFERROR(VLOOKUP(E25,'Dados dos moldes'!$B$2:$C$250,2,FALSE),"") -> Tampinha Esferográfica | G24: =IFERROR(VLOOKUP(H25,'Dados dos moldes'!$B$2:$C$250,2,FALSE),"") -> Corpo 07 / Economic | J24: =IFERROR(VLOOKUP(K25,'Dados dos moldes'!$B$2:$C$250,2,FALSE),"") -> Tampinha Esferográfica | M24: =IFERROR(VLOOKUP(N25,'Dados dos moldes'!$B$2:$C$250,2,FALSE),"") -> Tampa Destaq
D25: MOLDE | E25: 201 | G25: MOLDE | H25: 197 | J25: MOLDE | K25: 140 | M25: MOLDE | N25: 162
D27: ENGEL 06
D28: =IFERROR(VLOOKUP(E29,'Dados dos moldes'!$B$2:$C$250,2,FALSE),"") -> Tampinha Neo Pen
D29: MOLDE | E29: 101
D31: ENGEL 33
D32: =IFERROR(VLOOKUP(E33,'Dados dos moldes'!$B$2:$C$250,2,FALSE),"") -> Sem Molde
D33: MOLDE | E33: -
G35: ROMI 42 | J35: ROMI 38 | M35: ROMI 43 | P35: ENGEL 05 | S35: ENGEL 03
G36: =IFERROR(VLOOKUP(H37,'Dados dos moldes'!$B$2:$C$250,2,FALSE),"") -> Bico de Cola | J36: =IFERROR(VLOOKUP(K37,'Dados dos moldes'!$B$2:$C$250,2,FALSE),"") -> Tampinha Destaq | M36: =IFERROR(VLOOKUP(N37,'Dados dos moldes'!$B$2:$C$250,2,FALSE),"") -> Conexão Esferográficas | P36: =IFERROR(VLOOKUP(Q37,'Dados dos moldes'!$B$2:$C$250,2,FALSE),"") -> Sem Molde | S36: =IFERROR(VLOOKUP(T37,'Dados dos moldes'!$B$2:$C$250,2,FALSE),"") -> Sem Molde
G37: MOLDE | H37: 11A | J37: MOLDE | K37: 163 | M37: MOLDE | N37: 168 | P37: MOLDE | Q37: - | S37: MOLDE | T37: -
D39: Consultas
D40: MOLDE | E40: DESCRIÇÃO | J40: MATERIA-PRIMA
E41: =IFERROR(VLOOKUP(D41,'Dados dos moldes'!E3:F150,2,FALSE),"") | J41: =IFERROR(VLOOKUP(D41,'Dados dos moldes'!E3:H150,4,FALSE),"") | L41: =IFERROR(VLOOKUP(D41,'Dados dos moldes'!E3:I150,5,FALSE),"")
C42: Todos os direitos reservados por Márcio Marques e Diogo de Jesus © 2025

Sheet Desenhos Técnicos
C54: Todos os direitos reservados por Márcio Marques e Lucas Ávila © 2025

Sheet Ficha Técnica
C54: Todos os direitos reservados por Márcio Marques e Lucas Ávila © 2025

Sheet Kanban
C1: KANBAN
AK35: Janeiro | AL35: 1 | AM35: 2020 | AN35: Inicio | AO35: =DATE(AB36,VLOOKUP(X36,AK35:AL46,2,FALSE),1) -> 46204
X36: Julho | AB36: 2026 | AK36: Fevereiro | AL36: 2 | AM36: 2021 | AN36: fim | AO36: =EOMONTH(AO35,0) -> 46234
X37: Dom | Y37: Seg | Z37: Ter | AA37: Qua | AB37: Qui | AC37: Sex | AD37: Sáb | AK37: Março | AL37: 3 | AM37: 2022 | AO37: =WEEKDAY(AO35,1) -> 4
X38: =AO35-AO37+1 -> 46201 | Y38: =X38+1 -> 46202 | Z38: =Y38+1 -> 46203 | AA38: =Z38+1 -> 46204 | AB38: =AA38+1 -> 46205 | AC38: =AB38+1 -> 46206 | AD38: =AC38+1 -> 46207 | AK38: Abril | AL38: 4 | AM38: 2023
X39: =AD38+1 -> 46208 | Y39: =X39+1 -> 46209 | Z39: =Y39+1 -> 46210 | AA39: =Z39+1 -> 46211 | AB39: =AA39+1 -> 46212 | AC39: =AB39+1 -> 46213 | AD39: =AC39+1 -> 46214 | AK39: Maio | AL39: 5 | AM39: 2024
X40: =AD39+1 -> 46215 | Y40: =X40+1 -> 46216 | Z40: =Y40+1 -> 46217 | AA40: =Z40+1 -> 46218 | AB40: =AA40+1 -> 46219 | AC40: =AB40+1 -> 46220 | AD40: =AC40+1 -> 46221 | AK40: Junho | AL40: 6 | AM40: 2025
X41: =AD40+1 -> 46222 | Y41: =X41+1 -> 46223 | Z41: =Y41+1 -> 46224 | AA41: =Z41+1 -> 46225 | AB41: =AA41+1 -> 46226 | AC41: =AB41+1 -> 46227 | AD41: =AC41+1 -> 46228 | AK41: Julho | AL41: 7 | AM41: 2026
X42: =AD41+1 -> 46229 | Y42: =X42+1 -> 46230 | Z42: =Y42+1 -> 46231 | AA42: =Z42+1 -> 46232 | AB42: =AA42+1 -> 46233 | AC42: =AB42+1 -> 46234 | AD42: =AC42+1 -> 46235 | AK42: Agosto | AL42: 8 | AM42: 2027
X43: =AD42+1 -> 46236 | Y43: =X43+1 -> 46237 | Z43: =Y43+1 -> 46238 | AA43: =Z43+1 -> 46239 | AB43: =AA43+1 -> 46240 | AC43: =AB43+1 -> 46241 | AD43: =AC43+1 -> 46242 | AK43: Setembro | AL43: 9 | AM43: 2028
AK44: Outubro | AL44: 10 | AM44: 2029
AK45: Novembro | AL45: 11 | AM45: 2030
AK46: Dezembro | AL46: 12 | AM46: 2031
C47: Todos os direitos reservados por Márcio Marques e Lucas Ávila © 2025

Sheet Calendário

Sheet Dados dos moldes
B1: MOLDES | C1: DESCRIÇÃO | E1: GRADE DE MOLDES
B2: 4 | E2: CUSTO | F2: DESCRIÇÃO | G2: CAV. | H2: MATERIA-PRIMA | J2: PROJETO | K2: FABRICANTE
B3: 29 | C3: Tampa estojo grafite 2mm | E3: 29 | F3: TAMPA DE ESTOJO GRAFITE 2mm | G3: 8 | J3: - | K3: COMPACTOR
B4: 36 | E4: 36 | F4: PEÇA 2 | G4: 32 | H4: ABS | I4: ABS | J4: MEB-12/03 | K4: COMPACTOR
B5: 37 | E5: 37 | F5: PEÇA 1 | G5: 28 | H5: ABS | I5: ABS | J5: MEC 11/01 | K5: COMPACTOR
B6: 61 | E6: 61 | F6: PORTA PEN GRANDE | G6: 1 | H6: PP400 | I6: POLIPROPILENO | J6: - | K6: COMPACTOR
B7: 69 | C7: Botão Lapiseira Turbo | E7: 69 | F7: BOTÃO LAPISEIRA TURBO | G7: 8 | H7: ABS | I7: ABS | J7: MLG 08/1 | K7: COMPACTOR
B8: 80 | C8: Tampinha Carga 1006 | E8: 89 | F8: CORPO ALUNO | G8: 16 | H8: ABS | I8: ABS | J8: 2378 | K8: MATOS
B9: 81 | E9: 97 | F9: TAMPINHA ESFEROGRÁFICA 07 E TOP | G9: 64 | H9: PEAD 20% + PEBD 80% | I9: POLIETILENO | J9: 47-01-2 | K9: LAMBRECHT
B10: 89 | C10: Corpo Lapiseira Aluno | E10: 98 | F10: CONEXÃO ESFEROGRÁFICA 07 E TOP | G10: 64 | H10: PP400 | I10: POLIPROPILENO | J10: 47-01-1+2 | K10: LAMBRECHT
B11: 97 | C11: Tampinha Esferográfica | E11: 101 | F11: TAMPINHA NEO-PEN | G11: 64 | H11: PP400 | I11: POLIPROPILENO | J11: 47-02-1 | K11: LAMBRECHT
B12: 98 | C12: Conexão Esferográficas | E12: 107 | F12: TAMPA ESFEROGRÁFICA TOP | G12: 64 | H12: PP400 | I12: POLIPROPILENO | J12: S-0199 | K12: SCHNEIDER
B13: 101 | C13: Tampinha Neo Pen | E13: 109 | F13: TAMPINHA COLOR | G13: 48 | H13: PP400 | I13: POLIPROPILENO | J13: 112 | K13: ABC
B14: 102 | C14: Tampa Neo Pen | E14: 110 | F14: TAMPA COLOR | G14: 48 | H14: PP FT120 | I14: POLIPROPILENO | J14: 110 | K14: ABC
B15: 107 | C15: Tampa Esf. Top | E15: 117 | F15: TAMPA ESFEROGRÁFICA 07 | G15: 64 | H15: PP400 | I15: POLIPROPILENO | J15: 47-10-1 | K15: LAMBRECHT
B16: 108 | C16: Corpo 07 / Economic | E16: 121 | F16: CORPO NEO-PEN MIRIM | G16: 64 | H16: PP400 | I16: POLIPROPILENO | J16: 47-14-1 | K16: LAMBRECHT
B17: 109 | C17: Tampinha Color | E17: 122 | F17: TAMPA NEO-PEN | G17: 48 | H17: PP FT120 | I17: POLIPROPILENO | J17: 47-11-1 | K17: LAMBRECHT
B18: 110 | C18: Tampa Color | E18: 128 | F18: APAGADOR QB | G18: 1 | H18: PP400 | I18: POLIPROPILENO | J18: AT-037 | K18: ALFATECNICS
B19: 115 | C19: Corpo 07 / Economic | E19: 129 | F19: TAMPA FRASCO DE COLA 250g - 500g - 1000g | G19: 4 | H19: PP FT120 | I19: POLIPROPILENO | J19: LKM 866 | K19: COREANO
B20: 116 | C20: Corpo Pincel | E20: 137 | F20: CORPO LAPISEIRA TURBO | G20: 8 | J20: WKZ-646 | K20: SCHNEIDER
B21: 117 | C21: Tampa Esf. 07 | E21: 139 | F21: TAMPA ESFEROGRÁFICA TOP | G21: 64 | H21: PP400 | I21: POLIPROPILENO | J21: S-0135 | K21: SCHNEIDER
B22: 118 | E22: 140 | F22: TAMPINHA ESFEROGRÁFICA 07 E TOP | G22: 64 | H22: PEAD 20% + PEBD 80% | I22: POLIETILENO | J22: 47-19-1 | K22: LAMBRECHT
B23: 120 | C23: Corpo NPG | E23: 146 | F23: TAMPINHA NEO-PEN | G23: 64 | H23: PP400 | I23: POLIPROPILENO | J23: 47-22-1 | K23: LAMBRECHT
B24: 121 | C24: Corpo NPM | E24: 148 | F24: CORPO COLOR | G24: 64 | H24: PP400 | I24: POLIPROPILENO | J24: 47-23-1 | K24: LAMBRECHT
B25: 122 | C25: Tampa Neo Pen | E25: 150 | F25: CONEXÃO MICROLINE | G25: 16 | H25: PP400 | I25: POLIPROPILENO | J25: SW 9987 | K25: COREANO
B26: 124 | C26: Tampa Marcador Maxx | E26: 151 | F26: TAMPINHA MICROLINE | G26: 16 | H26: PP400 | I26: POLIPROPILENO | J26: SW 9988 | K26: COREANO
B27: 125 | C27: Tampinha Marcador Maxx | E27: 152 | F27: TAMPA MICROLINE | G27: 16 | H27: PP400 | I27: POLIPROPILENO | J27: SW 9986 | K27: COREANO
B28: 126 | C28: Corpo Marcador Maxx | E28: 153 | F28: CORPO 07 PLUS | G28: 16 | J28: SW 1066 | K28: COREANO
B29: 127 | E29: 154 | F29: TAMPA 07 PLUS | G29: 16 | H29: POLICABORNATO | I29: POLICABORNATO | J29: SW 1065 | K29: COREANO
B30: 128 | C30: Apagador | E30: 156 | F30: CONEXÃO ESFEROGRÁFICA 140mm | G30: 16 | J30: 1087 | K30: COREANO
B31: 129 | C31: Tampa para Cola 1000g | E31: 157 | F31: BICO PARA REABASTECEDOR | G31: 16 | H31: PP FT120 | I31: POLIPROPILENO | J31: AT-096 | K31: ALFATECNICS
B32: 137 | C32: Corpo Lapiseira Turbo | E32: 158 | F32: BOTÃO LAPISEIRA TÉCNICO | G32: 16 | H32: ABS | I32: ABS | J32: HKB 121-1 | K32: COREANO
B33: 138 | C33: Corpo Top | E33: 159 | F33: CORPO LAPISEIRA TÉCNICO | G33: 16 | H33: ABS | I33: ABS | J33: HKB 120 | K33: COREANO
B34: 139 | C34: Tampa Esf. Top | E34: 160 | F34: PONTEIRA LAPISEIRA TÉCNICO | G34: 16 | H34: PP400 | I34: POLIPROPILENO | J34: HKB 119 | K34: COREANO
B35: 140 | C35: Tampinha Esferográfica | E35: 162 | F35: TAMPA MARCADOR DESTAQ | G35: 16 | H35: PP400 | I35: POLIPROPILENO | J35: SW 1244 | K35: COREANO
B36: 141 | E36: 163 | F36: TAMPINHA MARCADOR DESTAQ | G36: 16 | H36: PP400 | I36: POLIPROPILENO | J36: SW 1246 | K36: COREANO
B37: 143 | C37: Corpo 07 / Economic | E37: 164 | F37: CORPO MARCADOR DESTAQ | G37: 16 | H37: PP400 | I37: POLIPROPILENO | J37: SW 1245 | K37: COREANO
B38: 144 | C38: Corpo NPG | E38: 165 | F38: CORPO ESFEROGRÁFICA 07 - ECONOMIC | G38: 64 | H38: PS-CRISTAL | I38: POLIESTIRENO | J38: 47-24-1 | K38: COMPACTOR
B39: 146 | C39: Tampinha Neo Pen | E39: 168 | F39: CONEXÃO ESFEROGRÁFICA 07 E TOP | G39: 64 | H39: PP400 | I39: POLIPROPILENO | J39: SW 1307 | K39: COREANO
B40: 148 | C40: Corpo Color | E40: 169 | F40: TAMPA NEO-PEN | G40: 64 | H40: PP FT120 | I40: POLIPROPILENO | J40: SW 1348 | K40: COREANO
...
